Workbook
Name ALTA: [1]INSTRUCTIVO!$J$1:$J$2
Name IMPACTO: [2]FÓRMULAS!$N$5:$N$9
Name IMPACTO: FÓRMULAS!$N$5:$N$9
Name NIVEL: FÓRMULAS!$B$5:$B$9
Name PROBABILIDAD: [2]FÓRMULAS!$B$5:$B$9
Name PROBABILIDAD: FÓRMULAS!$B$5:$B$9
Name www.uts.edu.co_portal_app_ckfinder_userfiles_files_LEY_2080_20DE_201993_Por_20la_20cual_20se_20expide_20el_20Estatuto_20General_20de_20Contrataci_C3_B3n_20de_20la_20Administraci_C3_B3n_20P_C3_BAblica.pdf: #REF!
Name www.uts.edu.co_portal_app_ckfinder_userfiles_files_LEY_2080_20DE_201993_Por_20la_20cual_20se_20expide_20el_20Estatuto_20General_20de_20Contrataci_C3_B3n_20de_20la_20Administraci_C3_B3n_20P_C3_BAblica.pdf: #REF!

Sheet FÓRMULAS
B3: PROBABILIDAD DE OCURRENCIA | N3: IMPACTO QUE GENERA EL RIESGO | T3: CLASES DE RIEGOS
B4: NIVEL | C4: CALIFICACIÓN | E4: DESCRIPCIÓN | H4: FRECUENCIA | N4: NIVEL | O4: CALIFICACIÓN | P4: DESCRIPCIÓN | T4: RIESGO | U4: DEFINICIÓN
B5: 1 | C5: RARA VEZ | E5: EL eento puede ocurrir sólo en circunstancias exepcionales (Poco comúnes o anormales) | H5: No se ha presentado en los últimos 5 años | N5: 1 | O5: Insignificante | P5: Si el hecho llegara a presentarse, tendría consecuencias o efectos mínimos sobre la entidad. | T5: Riesgo Estratégico | U5: Se asocia con la forma en que se administra la Entidad, su manejo se enfoca a asuntos globales relacionados con la misión y el cumplimiento de los objetivos estratégicos, la clara definición de políticas, diseño y conceptualización de la entidad por parte de la alta gerencia.
B6: 2 | C6: IMPROBABLE | E6: El evento puede ocurir en algún momento | H6: Al menos una vez en los últimos 5 años | N6: 2 | O6: Menor | P6: Si el hecho llegara a presentarse, tendría bajo impacto o efecto sobre la entidad. | T6: Riesgos de Imagen | U6: Están relacionados con la percepción y la confianza por parte de la ciudadanía hacia la institución.
B7: 3 | C7: POSIBLE | E7: El evento podrá ocurrir en algún momento | H7: Al menos una vez en los últimos 2 años | N7: 3 | O7: Moderado | P7: Si el hecho llegara a presentarse, tendría medianas consecuencias o efectos sobre la entidad. | T7: Riesgos Operativos | U7: Comprenden riesgos provenientes del funcionamiento y operatividad de los sistemas de información institucional, de la definición de los procesos, de la estructura de la entidad, de la articulación entre dependencias.
B8: 4 | C8: PROBABLE | E8: Es viable que el evento ocurra en la mayoría de las circunstancias | H8: Al menos una vez en el último año | N8: 4 | O8: Mayor | P8: Si el hecho llegara a presentarse, tendría altas consecuencias o efectos sobre la entidad. | T8: Riesgos Financieros | U8: Se relacionan con el manejo de los recursos de la entidad que incluyen la ejecución presupuestal, la elaboración de los estados financieros, los pagos, manejos de excedentes de tesorería y el manejo sobre los bienes.
B9: 5 | C9: CASI SEGURO | E9: Se espera que el evento ocurra en la mayoria de las circunstancias | H9: Más de una vez al año | N9: 5 | O9: Catastrófico | P9: Si el hecho llegara a presentarse, tendría desastrosas consecuencias o efectos sobre la entidad. | T9: Riesgos de Cumplimiento | U9: Se asocian con la capacidad de la entidad para cumplir con los requisitos legales, contractuales, de ética pública y en general con su compromiso ante la comunidad.
T10: Riesgos de Tecnología | U10: Están relacionados con la capacidad tecnológica de la Entidad para satisfacer sus necesidades actuales y futuras y el cumplimiento de la misió
T11: Riesgos de Corrupción | U11: Relacionados con acciones, omisiones, uso indebido del poder, de los recursos o de la información para la obtención de un beneficio particular o de un tercero.
A15: 3)
B16: EVALUACIÓN DEL RIESGO
N17: DEFINICIONES DE CONTROLES | T17: POSIBLES CONTROLES
B18: 5 Casi Seguro | C18: ALTO | E18: ALTO | G18: EXTREMO | I18: EXTREMO | K18: EXTREMO | N18: CONTROLES PREVENTIVOS | O18: Evitan que un evento suceda. Por ejemplo el requerimiento de un login y password en un sistema de información es un control preventivo. Éste previene (teóricamente) que personas no autorizadas puedan ingresar al sistema. Dentro de esta categoría pueden existir controles de tipo detectivo, los cuales permiten registrar un evento después de que ha sucedido, por ejemplo, registro de las entradas de todas las actividades llevadas a cabo en el sistema de información, traza de los registros realizados, de las personas que ingresaron, entre otros. | T18: POLÍTICAS CLARAS APLICADAS | U18: Políticas claras aplicadas Seguimiento al plan estratégico y operativo Indicadores de gestión Tableros de control Seguimiento a cronograma Informes de gestión
B20: 4 Probable | C20: MODERADO | E20: ALTO | G20: ALTO | I20: EXTREMO | K20: EXTREMO
T21: POLÍTICAS CLARAS APLICADAS | U21: Conciliaciones Consecutivos Verificación de firmas Listas de chequeo Registro controlado Segregación de funciones Niveles de autorizción Custodia apropiada Procedimeintos formales aplicados Pólizas Seguridad física Contingencias y respaldo Personal capacitado Aseguramiento y calidad
B22: 3 Posible | C22: BAJO | E22: MODERADO | G22: ALTO | I22: EXTREMO | K22: EXTREMO | N22: CONTROLES CORRECTIVOS | O22: Éstos no prevén que un evento suceda, pero permiten enfrentar la situación una vez se ha presentado. Por ejemplo en caso de un desastre natural u otra emergencia mediante las pólizas de seguro y otros mecanismos de recuperación de negocio o respaldo, es posible volver a recuperar las operaciones
B24: 2 Improbable | C24: BAJO | E24: BAJO | G24: MODERADO | I24: ALTO | K24: EXTREMO
B26: 1 Rara Vez | C26: BAJO | E26: BAJO | G26: MODERADO | I26: ALTO | K26: ALTO | N26: CONTROLES AUTOMATICOS | O26: Utilizan herramientas tecnológicas como sistemas de información o software que permiten incluir contraseñas de acceso, o con controles de seguimiento a aprobaciones o ejecuciones que se realizan a través de éste, generación de reportes o indicadores, sistemas de seguridad con scanner, sistemas de grabación, entre otros. Este tipo de controles suelen ser más efectivos en algunos ámbitos dada su complejidad
C27: 1 Insignificante | E27: 2 Menor | G27: 3 Moderado | I27: 4 Mayor | K27: 5 Catastrófico
N28: CONTROLES MANUALES | O28: Políticas de operación aplicables, autorizaciones a través de firmas o confirmaciones vía correo electrónico, archivos físicos, consecutivos, listas de chequeo, controles de seguridad con personal especializado, entre otros
T29: NORMAS CLARAS Y APLICADAS | U29: Normas claras y aplicadas Control de términos
B39: OPCIÓN DE MANEJO | D39: DESCRIPCIÓN | N39: ZONA DE RIESGO O NIVEL DE EXPOSICION
B40: REDUCIR | D40: Medidas encaminadas a disminuir tanto la probabilidad (medidas de prevención) como el impacto (medidas de protección). Se consigue mediante la optimización de los procedimientos y la implementación de controles. | N40: Zona | O40: Descripción
B41: EVITAR | D41: Medida encaminada a eliminar la actividad que genera el riesgo previniendo su materialización. | N41: BAJA | O41: Riesgo BAJO, se puede aceptar el riesgo
B42: TRANSFERIR | D42: Medida encaminada a eliminar el riesgo transfiriéndolo de un lugar a otro. Consiste, por ejemplo, en vender un activo dudoso, asegurar una actividad con importantes riesgos, etc. | N42: MODERADO | O42: Riesgo MODERADO, se debe aceptar o reducir el riesgo.
B43: ACEPTAR | D43: Asumir (aceptar) la presencia de un riesgo mínimo o residual después de que el riesgo se ha reducido o transferido. Para ello se debe contar con planes de contingencia. | N43: ALTA | O43: Riesgo ALTO, debe ser reducido, evitado, compartido o transferido
N44: EXTREMA | O44: Riesgo EXTREMO, debe ser reducido, evitado, compartido o transferido
B54: CATEGORÍA DEL RIESGO | I54: TIPOLOGÍA DEL RIESGO | M54: ¿El control afecta la probabilidad o afecta el impacto? | P54: RESPUESTA | Q54: 14. ¿Cómo es el control?
B55: GESTIÓN | I55: ESTRATÉGICOS | M55: PROBABILIDAD | P55: SI | Q55: MANUAL
B56: CORRUPCIÓN | I56: DE IMAGEN | M56: IMPACTO | P56: NO | Q56: AUTOMÁTICO
B57: SEGURIDAD DE LA INFORMACIÓN | I57: OPERATIVOS
I58: FINANCIEROS
I59: DE CUMPLIMIENTO
I60: DE TECNOLOGÍA
I61: DE SEGURIDAD DIGITAL

Sheet Intructivo
B2: Matriz Mapa de Riesgos
B4: Teniendo en cuenta que con la expedición del Decreto 1499 de 2017 “Por medio del cual se modifica el Decreto 1083 de 2015, Decreto Único Reglamentario del Sector Función Pública, en lo relacionado con el Sistema de Gestión establecido en el artículo 133 de la Ley 1753 de 2015”, se crea un solo Sistema de Gestión y se alinea con el Sistema de Control Interno, hoy todas las entidades públicas requieren actualizar y/o implementar el Modelo Integrado de Planeación y Gestión MIPG, modelo que incorpora el Modelo Estándar de Control Interno MECI a través de la 7a dimensión del mismo. En este marco general, el proceso de administración del riesgo es un esfuerzo conjunto entre la Alta Dirección y los servidores en todos sus niveles, ejercicio que inicia con la formulación de la política de Administración del Riesgo, la cual incluye los niveles de responsabilidad frente al seguimiento y evaluación, aspectos que deberán definirse acorde con el Esquema de Líneas de Defensa vinculado a la Dimensión 7. Teniendo en cuenta lo anterior y dada la necesidad de las entidades frente a la estructuración de los mapas de riesgos, como herramienta fundamental frente a la gestión del riesgo, el presente formato desarrolla un esquema completo acorde con los contenidos metodológicos de la Guía para la Administración del Riesgo y el diseño de controles V5. El formato cuenta con celdas parametrizadas y permite contar con los respectivos mapas de calor para riesgo inherente y riesgo residual.
B6: Orientaciones Generales
B7: Antes de iniciar con el diligenciamiento de la información en la matriz, se requiere haber avanzado en el análisis del proceso, su objetivo, alcance, actividades clave, considere los lineamientos establecidos en el Paso 2: identificación del riesgo, donde se explica ampliamente las bases para adelanter este análisis. Así mismo, considere en el Paso 3: valoración del riesgo los lineamientos para definir el No. de veces que se hace la actividad con la cual se relaciona el riesgo y su impacto en términos económicos o reputacionales. En este mismo paso se analizan los controles que deben responder a los atributos de eficiencia e informativos. NOTA: Si lo considera pertinente, es posible agregar hojas de trabajo adicionales al presente formato que permitan incluir la traza de estos análisis.
B9: El archivo contiene las siguientes hojas: - Hoja 1 Instructivo - Hoja 2 Mapa Final: Encontrará la totalidad de la estructura para la identificación y valoración de los riesgos por proceso, programa o proyecto, acorde con el nivel de desagregación que la entidad considere necesaria.
C12: Columna | E12: Descripción - Lineamientos para el diligenciamiento
C13: Proceso | E13: Diligencie el nombre del proceso al cual se le identificarán y valorarán los riesgos.
C14: Objetivo | E14: Diligencie el objetivo del proceso.
C15: Alcance | E15: Diligencie el alcance del proceso.
C16: Referencia | E16: Permite definir unl consecutivo de riesgos. Una entidad puede ir en el riesgo 150, pero tener 70 riesgos, lo que permite llevar una traza de los riesgos. Esta información la debe administrar la oficina asesora de planeación o gerencia de riesgos. Cuando un el riesgo salga del mapa no existirá otro riesgo con el mismo número.
C17: Impacto | E17: Analice las consecuencias que puede ocasionar a la organización la materialización del riesgo, redacte de la forma más concreta posible.
C18: Causa Inmediata | E18: Circunstancias bajo las cuales se presenta el riesgo, es la situación más evidente frente al riesgo, redacte de la forma más concreta posible.
C19: Causa Raíz | E19: Causa principal o básica, corresponde a las razones por la cuales se puede presentar el riesgo, redacte de la forma más concreta posible.
C20: Descripción del Riesgo | E20: Consolida o resume los análisis sobre impacto + causa inmediata + causa raíz, permitiendo contar con una redacción clara y concreta del riesgo indentificado. Tenga en cuenta la estructura de alto nivel establecida en al guía, inicia con POSIBILIDAD DE + Impacto para la entidad (Qué) + Causa Inmediata (Cómo) + Causa Raíz (Por qué)
C21: Clasificación del Riesgo | E21: Utilice la lista de despligue que se encuentra parametrizada, le aparecerán las opciones: i)Daños Activos Fisicos, ii)Ejecucion y Administracion de procesos, iii)Fallas Tecnologicas, iv)Fraude Externo, v)Fraude Interno, vi)Relaciones Laborales, vii)Usuarios, productos y practicas organizacionales.
C22: Frecuencia con la cual se lleva a cabo la actividad | E22: Defina el # de veces que se ejecuta la actividad durante el año, (Recuerde la probabilidad e ocurrencia del riesgo se defien como el No. de veces que se pasa por el punto de riesgo en el periodo de 1 año). La matriz automáticamente hará el cálculo para el nivel de probabilidad inherente (Columnas H-I)
C23: Criterios de Impacto | E23: Utilice la lista de despligue que se encuentra parametrizada, le aparecerán las opciones de la tabla de Impacto en la Hoja 6 del presente documento. La matriz automáticamente hará el cálculo para el nivel de impacto inherente (Columnas L-M)
... C37: Estado | E37: Utilice la lista de despligue que se encuentra parametrizada, le aparecerán las opciones: i)Finalizado, ii)En curso, la selección en este caso dependerá de las acciones del plan que se hayan establecido en cada caso.
B40: - Hoja 3 Matriz de Calor Inherente: En esta hoja, en la medida en que ese diligencia el Mapa Final, se verán reflejados los riesgos en su zona correspondiente. Esta hoja no se diligencia se genera de manera automática.
B41: - Hoja 4 Matriz de Calor Residual: En esta hoja, en la medida en que ese diligencia el Mapa Final, se verán reflejados los riesgos en su zona correspondiente. Esta hoja no se diligencia se genera de manera automática.
B42: - Hoja 5 Tabla de probabilidad: Tabla referente para todos los cálculos (no se diligencia)
B43: - Hoja 6 Tabla de Impacto: Tabla referente para todos los cálculos (no se diligencia)
B44: - Hoja 7 Tabla de Valoración de Controles: Tabla referente para todos los cálculos (no se diligencia)

Sheet DOFA
D1: PLANEACIÓN INSTITUCIONAL MAPA DE RIESGOS INSTITUCIONAL MATRIZ DE CONTEXTO ESTRATÉGICO DE RIESGOS DEL PROCESO DOFA | L1: PÁGINA: 1
L2: DE: 5
L3: VERSIÓN: 7.0
B4: F - PL - 13
A6: PROCESO: | D6: Admisiones y Matrículas | G6: RESPONSABLE: | I6: Coordinador de Admisiones, Registro Y Control Académico
A7: FECHA DE ACTUALIZACIÓN: | D7: 44682
A9: INTERNAS | B9: FORTALEZAS | H9: DEBILIDADES
B10: 1. Personal idóneo para el cumplimiento de las actividades | H10: 1. Insumos de papelería deficientes
B11: 2. Equipos de tecnológicos actualizados | H11: 2. Falta de integración del software académico con el financiero
B12: 3. Instalaciones locativas eficientes | H12: 3.
B13: 4. Personal capacitado constantemente | H13: 4.
B14: 5. | H14: 5.
A19: EXTERNAS | B19: OPORTUNIDADES | H19: AMENAZAS
B20: 1. Adquisición de paquete financiero para la integración del software académico | H20: 1. Perdida de la información por aspectos naturales
B21: 2. Apoyo de los entes gubernamentales para becas estudiantiles | H21: 2. Perdida de la población estudiantil por economía
B22: 3. Convenio con medios de comunicación para la divulgación de temas pertinentes al proceso | H22: 3. Perdida de la población estudiantil por competencia
B23: 4. | H23: 4. Cortes de energía eléctrica
B24: 5. | H24: 5.
A29: ELABORADO POR: | C29: PLANEACIÓN INSTITUCIONAL | E29: REVISADO POR: | F29: SISTEMA INTEGRADO DE GESTIÓN | I29: APROBADO POR: | K29: LÍDER DEL SISTEMA INTEGRADO DE GESTIÓN
I30: FECHA APROBACIÓN: | K30: ABRIL DE 2022

Sheet Mapa de Riesgos
D1: PLANEACIÓN INSTITUCIONAL | AE1: PÁGINA 2 DE 5
A2: F - PL - 13 | D2: MAPA DE RIESGOS INSTITUCIONAL | AE2: VERSIÓN: 7.0
A4: NOMBRE DEL PROCESO | D4: ADMISIONES Y MATRÍCULAS | N4: VIGENCIA
A5: DEPENDENCIA/GRUPO/OFICINA | D5: Grupo de Admisiones, Registro y Control Académico | N5: NOMBRE Y CARGO DEL LÍDER
A7: IDENTIFICACIÓN DEL RIESGO | H7: ANÁLISIS DEL RIESGO INHERENTE | Q7: EVALUACIÓN DEL RIESGO - VALORACIÓN DE LOS CONTROLES | Z7: EVALUACIÓN DEL RIESGO - NIVEL DEL RIESGO RESIDUAL
A8: No. Riesgo | B8: Categoría del Riesgo | C8: Clasificación del Riesgo | D8: Descripción del Riesgo | E8: Factores | F8: Causas | G8: Consecuencias | H8: Frecuencia (Número de veces al año que realiza la actividad que causa el riesgo) | I8: Probabilidad Inherente | J8: % | K8: Impacto | L8: Criterios de impacto | M8: Observación de criterio | N8: Impacto Inherente | O8: % | P8: Zona de Riesgo Inherente | Q8: No. Control | R8: Descripción del Control | S8: Afectación | T8: Atributos | Z8: Probabilidad Residual | AA8: Probabilidad Residual Final | AB8: % | AC8: Impacto Residual Final | AD8: % | AE8: Zona de Riesgo Final | AF8: Tratamiento
T9: Tipo | U9: Implementación | V9: Calificación | W9: Documentación | X9: Frecuencia | Y9: Evidencia
A10: 1 | B10: GESTIÓN | C10: Usuarios, productos y practicas , organizacionales | D10: Atención no oportuna durante el proceso de inscripción. | E10: Factores Internos (Debilidades) | F10: 1. Insuficiencia de personal para la atención. 2. Falta de conocimiento sobre el proceso | G10: 1. Pérdida de aspirantes 2. Disminución de ingresos económicos | H10: 2 | I10: =IF(H10<=0,"",IF(H10<=2,"Muy Baja",IF(H10<=24,"Baja",IF(H10<=500,"Media",IF(H10<=5000,"Alta","Muy Alta"))))) -> Muy Baja | J10: =IF(I10="","",IF(I10="Muy Baja",0.2,IF(I10="Baja",0.4,IF(I10="Media",0.6,IF(I10="Alta",0.8,IF(I10="Muy Alta",1,)))))) -> 0.2 | K10: Económico y Reputacional | L10: Afectación menor a 10 SMLMV . | M10: =IF(NOT(ISERROR(MATCH(L10,'Tabla Impacto'!$B$221:$B$223,0))),'Tabla Impacto'!$F$223&"Por favor no seleccionar los criterios de impacto(Afectación Económica o presupuestal y Pérdida Reputacional)",L10) -> Afectación menor a 10 SMLMV . | N10: =IF(OR(M10='Tabla Impacto'!$C$11,M10='Tabla Impacto'!$D$11),"Leve",IF(OR(M10='Tabla Impacto'!$C$12,M10='Tabla Impacto'!$D$12),"Menor",IF(OR(M10='Tabla Impacto'!$C$13,M10='Tabla Impacto'!$D$13),"Moderado",IF(OR(M10='Tabla Impacto'!$C$14,M10='Tabla Impacto'!$D$14),"Mayor",IF(OR(M10='Tabla Impacto'!$C$15,M10='Tabla Impacto'!$D$15),"Catastrófico",""))))) -> Leve | O10: =IF(N10="","",IF(N10="Leve",0.2,IF(N10="Menor",0.4,IF(N10="Moderado",0.6,IF(N10="Mayor",0.8,IF(N10="Catastrófico",1,)))))) -> 0.2 | P10: =IF(OR(AND(I10="Muy Baja",N10="Leve"),AND(I10="Muy Baja",N10="Menor"),AND(I10="Baja",N10="Leve")),"Bajo",IF(OR(AND(I10="Muy baja",N10="Moderado"),AND(I10="Baja",N10="Menor"),AND(I10="Baja",N10="Moderado"),AND(I10="Media",N10="Leve"),AND(I10="Media",N10="Menor"),AND(I10="Media",N10="Moderado"),AND(I10="Alta",N10="Leve"),AND(I10="Alta",N10="Menor")),"Moderado",IF(OR(AND(I10="Muy Baja",N10="Mayor"),AND(I10="Baja",N10="Mayor"),AND(I10="Media",N10="Mayor"),AND(I10="Alta",N10="Moderado"),AND(I10="Alta",N10="Mayor"),AND(I10="Muy Alta",N10="Leve"),AND(I10="Muy Alta",N10="Menor"),AND(I10="Muy Alta",N10="Moderado"),AND(I10="Muy Alta",N10="Mayor")),"Alto",IF(OR(AND(I10="Muy Baja",N10="Catastrófico"),AND(I10="Baja",N10="Catastrófico"),AND(I10="Media",N10="Catastrófico"),AND(I10="Alta",N10="Catastrófico"),AND(I10="Muy Alta",N10="Catastrófico")),"Extremo","")))) -> Bajo | Q10: 1 | R10: Capacitaciones sobre atención al público y del proceso de inscripción, al personal del grupo de admisiones, registro y control académico | S10: =IF(OR(T10="Preventivo",T10="Detectivo"),"Probabilidad",IF(T10="Correctivo","Impacto","")) -> Probabilidad | T10: Preventivo | U10: Manual | V10: =IF(AND(T10="Preventivo",U10="Automático"),"50%",IF(AND(T10="Preventivo",U10="Manual"),"40%",IF(AND(T10="Detectivo",U10="Automático"),"40%",IF(AND(T10="Detectivo",U10="Manual"),"30%",IF(AND(T10="Correctivo",U10="Automático"),"35%",IF(AND(T10="Correctivo",U10="Manual"),"25%","")))))) -> 40% | W10: Documentado | X10: Aleatoria | Y10: Con Registro | Z10: =IFERROR(IF(S10="Probabilidad",(J10-(+J10*V10)),IF(S10="Impacto",J10,"")),"") -> 0.12 | AA10: =IFERROR(IF(Z10="","",IF(Z10<=0.2,"Muy Baja",IF(Z10<=0.4,"Baja",IF(Z10<=0.6,"Media",IF(Z10<=0.8,"Alta","Muy Alta"))))),"") -> Muy Baja | AB10: =+Z10 -> 0.12 | AC10: =IFERROR(IF(AD10="","",IF(AD10<=0.2,"Leve",IF(AD10<=0.4,"Menor",IF(AD10<=0.6,"Moderado",IF(AD10<=0.8,"Mayor","Catastrófico"))))),"") -> Leve | AD10: =IFERROR(IF(S10="Impacto",(O10-(+O10*V10)),IF(S10="Probabilidad",O10,"")),"") -> 0.2 | AE10: =IFERROR(IF(OR(AND(AA10="Muy Baja",AC10="Leve"),AND(AA10="Muy Baja",AC10="Menor"),AND(AA10="Baja",AC10="Leve")),"Bajo",IF(OR(AND(AA10="Muy baja",AC10="Moderado"),AND(AA10="Baja",AC10="Menor"),AND(AA10="Baja",AC10="Moderado"),AND(AA10="Media",AC10="Leve"),AND(AA10="Media",AC10="Menor"),AND(AA10="Media",AC10="Moderado"),AND(AA10="Alta",AC10="Leve"),AND(AA10="Alta",AC10="Menor")),"Moderado",IF(OR(AND(AA10="Muy Baja",AC10="Mayor"),AND(AA10="Baja",AC10="Mayor"),AND(AA10="Media",AC10="Mayor"),AND(AA10="Alta",AC10="Moderado"),AND(AA10="Alta",AC10="Mayor"),AND(AA10="Muy Alta",AC10="Leve"),AND(AA10="Muy Alta",AC10="Menor"),AND(AA10="Muy Alta",AC10="Moderado"),AND(AA10="Muy Alta",AC10="Mayor")),"Alto",IF(OR(AND(AA10="Muy Baja",AC10="Catastrófico"),AND(AA10="Baja",AC10="Catastrófico"),AND(AA10="Media",AC10="Catastrófico"),AND(AA10="Alta",AC10="Catastrófico"),AND(AA10="Muy Alta",AC10="Catastrófico")),"Extremo","")))),"") -> Bajo | AF10: Reducir (mitigar)
M11: =IF(NOT(ISERROR(MATCH(L11,_xlfn.ANCHORARRAY(#REF!),0))),#REF!&"Por favor no seleccionar los criterios de impacto",L11) -> 0 | Q11: 2 | R11: Capacitaciones sobre atención al público y del proceso de inscripción, al personal del grupo de admisiones, registro y control académico | S11: =IF(OR(T11="Preventivo",T11="Detectivo"),"Probabilidad",IF(T11="Correctivo","Impacto","")) -> Probabilidad | T11: Preventivo | U11: Manual | V11: =IF(AND(T11="Preventivo",U11="Automático"),"50%",IF(AND(T11="Preventivo",U11="Manual"),"40%",IF(AND(T11="Detectivo",U11="Automático"),"40%",IF(AND(T11="Detectivo",U11="Manual"),"30%",IF(AND(T11="Correctivo",U11="Automático"),"35%",IF(AND(T11="Correctivo",U11="Manual"),"25%","")))))) -> 40% | W11: Documentado | X11: Aleatoria | Y11: Con Registro | Z11: =IFERROR(IF(AND(S10="Probabilidad",S11="Probabilidad"),(AB10-(+AB10*V11)),IF(S11="Probabilidad",(J10-(+J10*V11)),IF(S11="Impacto",AB10,""))),"") -> 0.072 | AA11: =IFERROR(IF(Z11="","",IF(Z11<=0.2,"Muy Baja",IF(Z11<=0.4,"Baja",IF(Z11<=0.6,"Media",IF(Z11<=0.8,"Alta","Muy Alta"))))),"") -> Muy Baja | AB11: =+Z11 -> 0.072 | AC11: =IFERROR(IF(AD11="","",IF(AD11<=0.2,"Leve",IF(AD11<=0.4,"Menor",IF(AD11<=0.6,"Moderado",IF(AD11<=0.8,"Mayor","Catastrófico"))))),"") -> Leve | AD11: =IFERROR(IF(AND(S10="Impacto",S11="Impacto"),(AD10-(+AD10*V11)),IF(S11="Impacto",(O10-(+O10*V11)),IF(S11="Probabilidad",AD10,""))),"") -> 0.2 | AE11: =IFERROR(IF(OR(AND(AA11="Muy Baja",AC11="Leve"),AND(AA11="Muy Baja",AC11="Menor"),AND(AA11="Baja",AC11="Leve")),"Bajo",IF(OR(AND(AA11="Muy baja",AC11="Moderado"),AND(AA11="Baja",AC11="Menor"),AND(AA11="Baja",AC11="Moderado"),AND(AA11="Media",AC11="Leve"),AND(AA11="Media",AC11="Menor"),AND(AA11="Media",AC11="Moderado"),AND(AA11="Alta",AC11="Leve"),AND(AA11="Alta",AC11="Menor")),"Moderado",IF(OR(AND(AA11="Muy Baja",AC11="Mayor"),AND(AA11="Baja",AC11="Mayor"),AND(AA11="Media",AC11="Mayor"),AND(AA11="Alta",AC11="Moderado"),AND(AA11="Alta",AC11="Mayor"),AND(AA11="Muy Alta",AC11="Leve"),AND(AA11="Muy Alta",AC11="Menor"),AND(AA11="Muy Alta",AC11="Moderado"),AND(AA11="Muy Alta",AC11="Mayor")),"Alto",IF(OR(AND(AA11="Muy Baja",AC11="Catastrófico"),AND(AA11="Baja",AC11="Catastrófico"),AND(AA11="Media",AC11="Catastrófico"),AND(AA11="Alta",AC11="Catastrófico"),AND(AA11="Muy Alta",AC11="Catastrófico")),"Extremo","")))),"") -> Bajo | AF11: Reducir (mitigar)
M12: =IF(NOT(ISERROR(MATCH(L12,_xlfn.ANCHORARRAY(#REF!),0))),#REF!&"Por favor no seleccionar los criterios de impacto",L12) -> 0 | Q12: 3 | S12: =IF(OR(T12="Preventivo",T12="Detectivo"),"Probabilidad",IF(T12="Correctivo","Impacto","")) | V12: =IF(AND(T12="Preventivo",U12="Automático"),"50%",IF(AND(T12="Preventivo",U12="Manual"),"40%",IF(AND(T12="Detectivo",U12="Automático"),"40%",IF(AND(T12="Detectivo",U12="Manual"),"30%",IF(AND(T12="Correctivo",U12="Automático"),"35%",IF(AND(T12="Correctivo",U12="Manual"),"25%","")))))) | Z12: =IFERROR(IF(AND(S11="Probabilidad",S12="Probabilidad"),(AB11-(+AB11*V12)),IF(AND(S11="Impacto",S12="Probabilidad"),(AB10-(+AB10*V12)),IF(S12="Impacto",AB11,""))),"") | AA12: =IFERROR(IF(Z12="","",IF(Z12<=0.2,"Muy Baja",IF(Z12<=0.4,"Baja",IF(Z12<=0.6,"Media",IF(Z12<=0.8,"Alta","Muy Alta"))))),"") | AB12: =+Z12 | AC12: =IFERROR(IF(AD12="","",IF(AD12<=0.2,"Leve",IF(AD12<=0.4,"Menor",IF(AD12<=0.6,"Moderado",IF(AD12<=0.8,"Mayor","Catastrófico"))))),"") | AD12: =IFERROR(IF(AND(S11="Impacto",S12="Impacto"),(AD11-(+AD11*V12)),IF(AND(S11="Probabilidad",S12="Impacto"),(AD10-(+AD10*V12)),IF(S12="Probabilidad",AD11,""))),"") | AE12: =IFERROR(IF(OR(AND(AA12="Muy Baja",AC12="Leve"),AND(AA12="Muy Baja",AC12="Menor"),AND(AA12="Baja",AC12="Leve")),"Bajo",IF(OR(AND(AA12="Muy baja",AC12="Moderado"),AND(AA12="Baja",AC12="Menor"),AND(AA12="Baja",AC12="Moderado"),AND(AA12="Media",AC12="Leve"),AND(AA12="Media",AC12="Menor"),AND(AA12="Media",AC12="Moderado"),AND(AA12="Alta",AC12="Leve"),AND(AA12="Alta",AC12="Menor")),"Moderado",IF(OR(AND(AA12="Muy Baja",AC12="Mayor"),AND(AA12="Baja",AC12="Mayor"),AND(AA12="Media",AC12="Mayor"),AND(AA12="Alta",AC12="Moderado"),AND(AA12="Alta",AC12="Mayor"),AND(AA12="Muy Alta",AC12="Leve"),AND(AA12="Muy Alta",AC12="Menor"),AND(AA12="Muy Alta",AC12="Moderado"),AND(AA12="Muy Alta",AC12="Mayor")),"Alto",IF(OR(AND(AA12="Muy Baja",AC12="Catastrófico"),AND(AA12="Baja",AC12="Catastrófico"),AND(AA12="Media",AC12="Catastrófico"),AND(AA12="Alta",AC12="Catastrófico"),AND(AA12="Muy Alta",AC12="Catastrófico")),"Extremo","")))),"")
M13: =IF(NOT(ISERROR(MATCH(L13,_xlfn.ANCHORARRAY(#REF!),0))),#REF!&"Por favor no seleccionar los criterios de impacto",L13) -> 0 | Q13: 4 | S13: =IF(OR(T13="Preventivo",T13="Detectivo"),"Probabilidad",IF(T13="Correctivo","Impacto","")) | V13: =IF(AND(T13="Preventivo",U13="Automático"),"50%",IF(AND(T13="Preventivo",U13="Manual"),"40%",IF(AND(T13="Detectivo",U13="Automático"),"40%",IF(AND(T13="Detectivo",U13="Manual"),"30%",IF(AND(T13="Correctivo",U13="Automático"),"35%",IF(AND(T13="Correctivo",U13="Manual"),"25%","")))))) | Z13: =IFERROR(IF(AND(S12="Probabilidad",S13="Probabilidad"),(AB12-(+AB12*V13)),IF(AND(S12="Impacto",S13="Probabilidad"),(AB11-(+AB11*V13)),IF(S13="Impacto",AB12,""))),"") | AA13: =IFERROR(IF(Z13="","",IF(Z13<=0.2,"Muy Baja",IF(Z13<=0.4,"Baja",IF(Z13<=0.6,"Media",IF(Z13<=0.8,"Alta","Muy Alta"))))),"") | AB13: =+Z13 | AC13: =IFERROR(IF(AD13="","",IF(AD13<=0.2,"Leve",IF(AD13<=0.4,"Menor",IF(AD13<=0.6,"Moderado",IF(AD13<=0.8,"Mayor","Catastrófico"))))),"") | AD13: =IFERROR(IF(AND(S12="Impacto",S13="Impacto"),(AD12-(+AD12*V13)),IF(AND(S12="Probabilidad",S13="Impacto"),(AD11-(+AD11*V13)),IF(S13="Probabilidad",AD12,""))),"") | AE13: =IFERROR(IF(OR(AND(AA13="Muy Baja",AC13="Leve"),AND(AA13="Muy Baja",AC13="Menor"),AND(AA13="Baja",AC13="Leve")),"Bajo",IF(OR(AND(AA13="Muy baja",AC13="Moderado"),AND(AA13="Baja",AC13="Menor"),AND(AA13="Baja",AC13="Moderado"),AND(AA13="Media",AC13="Leve"),AND(AA13="Media",AC13="Menor"),AND(AA13="Media",AC13="Moderado"),AND(AA13="Alta",AC13="Leve"),AND(AA13="Alta",AC13="Menor")),"Moderado",IF(OR(AND(AA13="Muy Baja",AC13="Mayor"),AND(AA13="Baja",AC13="Mayor"),AND(AA13="Media",AC13="Mayor"),AND(AA13="Alta",AC13="Moderado"),AND(AA13="Alta",AC13="Mayor"),AND(AA13="Muy Alta",AC13="Leve"),AND(AA13="Muy Alta",AC13="Menor"),AND(AA13="Muy Alta",AC13="Moderado"),AND(AA13="Muy Alta",AC13="Mayor")),"Alto",IF(OR(AND(AA13="Muy Baja",AC13="Catastrófico"),AND(AA13="Baja",AC13="Catastrófico"),AND(AA13="Media",AC13="Catastrófico"),AND(AA13="Alta",AC13="Catastrófico"),AND(AA13="Muy Alta",AC13="Catastrófico")),"Extremo","")))),"")
M14: =IF(NOT(ISERROR(MATCH(L14,_xlfn.ANCHORARRAY(#REF!),0))),#REF!&"Por favor no seleccionar los criterios de impacto",L14) -> 0 | Q14: 5 | S14: =IF(OR(T14="Preventivo",T14="Detectivo"),"Probabilidad",IF(T14="Correctivo","Impacto","")) | V14: =IF(AND(T14="Preventivo",U14="Automático"),"50%",IF(AND(T14="Preventivo",U14="Manual"),"40%",IF(AND(T14="Detectivo",U14="Automático"),"40%",IF(AND(T14="Detectivo",U14="Manual"),"30%",IF(AND(T14="Correctivo",U14="Automático"),"35%",IF(AND(T14="Correctivo",U14="Manual"),"25%","")))))) | Z14: =IFERROR(IF(AND(S13="Probabilidad",S14="Probabilidad"),(AB13-(+AB13*V14)),IF(AND(S13="Impacto",S14="Probabilidad"),(AB12-(+AB12*V14)),IF(S14="Impacto",AB13,""))),"") | AA14: =IFERROR(IF(Z14="","",IF(Z14<=0.2,"Muy Baja",IF(Z14<=0.4,"Baja",IF(Z14<=0.6,"Media",IF(Z14<=0.8,"Alta","Muy Alta"))))),"") | AB14: =+Z14 | AC14: =IFERROR(IF(AD14="","",IF(AD14<=0.2,"Leve",IF(AD14<=0.4,"Menor",IF(AD14<=0.6,"Moderado",IF(AD14<=0.8,"Mayor","Catastrófico"))))),"") | AD14: =IFERROR(IF(AND(S13="Impacto",S14="Impacto"),(AD13-(+AD13*V14)),IF(AND(S13="Probabilidad",S14="Impacto"),(AD12-(+AD12*V14)),IF(S14="Probabilidad",AD13,""))),"") | AE14: =IFERROR(IF(OR(AND(AA14="Muy Baja",AC14="Leve"),AND(AA14="Muy Baja",AC14="Menor"),AND(AA14="Baja",AC14="Leve")),"Bajo",IF(OR(AND(AA14="Muy baja",AC14="Moderado"),AND(AA14="Baja",AC14="Menor"),AND(AA14="Baja",AC14="Moderado"),AND(AA14="Media",AC14="Leve"),AND(AA14="Media",AC14="Menor"),AND(AA14="Media",AC14="Moderado"),AND(AA14="Alta",AC14="Leve"),AND(AA14="Alta",AC14="Menor")),"Moderado",IF(OR(AND(AA14="Muy Baja",AC14="Mayor"),AND(AA14="Baja",AC14="Mayor"),AND(AA14="Media",AC14="Mayor"),AND(AA14="Alta",AC14="Moderado"),AND(AA14="Alta",AC14="Mayor"),AND(AA14="Muy Alta",AC14="Leve"),AND(AA14="Muy Alta",AC14="Menor"),AND(AA14="Muy Alta",AC14="Moderado"),AND(AA14="Muy Alta",AC14="Mayor")),"Alto",IF(OR(AND(AA14="Muy Baja",AC14="Catastrófico"),AND(AA14="Baja",AC14="Catastrófico"),AND(AA14="Media",AC14="Catastrófico"),AND(AA14="Alta",AC14="Catastrófico"),AND(AA14="Muy Alta",AC14="Catastrófico")),"Extremo","")))),"")
M15: =IF(NOT(ISERROR(MATCH(L15,_xlfn.ANCHORARRAY(#REF!),0))),#REF!&"Por favor no seleccionar los criterios de impacto",L15) -> 0 | Q15: 6 | S15: =IF(OR(T15="Preventivo",T15="Detectivo"),"Probabilidad",IF(T15="Correctivo","Impacto","")) | V15: =IF(AND(T15="Preventivo",U15="Automático"),"50%",IF(AND(T15="Preventivo",U15="Manual"),"40%",IF(AND(T15="Detectivo",U15="Automático"),"40%",IF(AND(T15="Detectivo",U15="Manual"),"30%",IF(AND(T15="Correctivo",U15="Automático"),"35%",IF(AND(T15="Correctivo",U15="Manual"),"25%","")))))) | Z15: =IFERROR(IF(AND(S14="Probabilidad",S15="Probabilidad"),(AB14-(+AB14*V15)),IF(AND(S14="Impacto",S15="Probabilidad"),(AB13-(+AB13*V15)),IF(S15="Impacto",AB14,""))),"") | AA15: =IFERROR(IF(Z15="","",IF(Z15<=0.2,"Muy Baja",IF(Z15<=0.4,"Baja",IF(Z15<=0.6,"Media",IF(Z15<=0.8,"Alta","Muy Alta"))))),"") | AB15: =+Z15 | AC15: =IFERROR(IF(AD15="","",IF(AD15<=0.2,"Leve",IF(AD15<=0.4,"Menor",IF(AD15<=0.6,"Moderado",IF(AD15<=0.8,"Mayor","Catastrófico"))))),"") | AD15: =IFERROR(IF(AND(S14="Impacto",S15="Impacto"),(AD14-(+AD14*V15)),IF(AND(S14="Probabilidad",S15="Impacto"),(AD13-(+AD13*V15)),IF(S15="Probabilidad",AD14,""))),"") | AE15: =IFERROR(IF(OR(AND(AA15="Muy Baja",AC15="Leve"),AND(AA15="Muy Baja",AC15="Menor"),AND(AA15="Baja",AC15="Leve")),"Bajo",IF(OR(AND(AA15="Muy baja",AC15="Moderado"),AND(AA15="Baja",AC15="Menor"),AND(AA15="Baja",AC15="Moderado"),AND(AA15="Media",AC15="Leve"),AND(AA15="Media",AC15="Menor"),AND(AA15="Media",AC15="Moderado"),AND(AA15="Alta",AC15="Leve"),AND(AA15="Alta",AC15="Menor")),"Moderado",IF(OR(AND(AA15="Muy Baja",AC15="Mayor"),AND(AA15="Baja",AC15="Mayor"),AND(AA15="Media",AC15="Mayor"),AND(AA15="Alta",AC15="Moderado"),AND(AA15="Alta",AC15="Mayor"),AND(AA15="Muy Alta",AC15="Leve"),AND(AA15="Muy Alta",AC15="Menor"),AND(AA15="Muy Alta",AC15="Moderado"),AND(AA15="Muy Alta",AC15="Mayor")),"Alto",IF(OR(AND(AA15="Muy Baja",AC15="Catastrófico"),AND(AA15="Baja",AC15="Catastrófico"),AND(AA15="Media",AC15="Catastrófico"),AND(AA15="Alta",AC15="Catastrófico"),AND(AA15="Muy Alta",AC15="Catastrófico")),"Extremo","")))),"")
A18: ELABORADO POR: | C18: PLANEACIÓN INSTITUCIONAL | G18: REVISADO POR: | H18: SISTEMA INTEGRADO DE GESTIÓN SIG | R18: APROBADO POR: | T18: LÍDER DEL SISTEMA INTEGRADO DE GESTIÓN
R19: FECHA APROBACIÓN | T19: ABRIL DE 2022

Sheet Plan de Acción
D1: ='Mapa de Riesgos'!D1 -> PLANEACIÓN INSTITUCIONAL | T1: PÁGINA 3 DE 5
A2: ='Mapa de Riesgos'!A2 -> F - PL - 13 | D2: ='Mapa de Riesgos'!D2 -> MAPA DE RIESGOS INSTITUCIONAL | T2: ='Mapa de Riesgos'!AE2 -> VERSIÓN: 7.0
A4: NOMBRE DEL PROCESO | D4: ='Mapa de Riesgos'!D4 -> ADMISIONES Y MATRÍCULAS | J4: VIGENCIA | N4: ='Mapa de Riesgos'!R4 -> 0
A5: DEPENDENCIA/GRUPO/OFICINA | D5: ='Mapa de Riesgos'!D5 -> Grupo de Admisiones, Registro y Control Académico | J5: NOMBRE Y CARGO DEL LÍDER | N5: ='Mapa de Riesgos'!R5 -> 0
A7: ='Mapa de Riesgos'!A7 -> IDENTIFICACIÓN DEL RIESGO | H7: ='Mapa de Riesgos'!H7 -> ANÁLISIS DEL RIESGO INHERENTE | I7: ='Mapa de Riesgos'!Q7 -> EVALUACIÓN DEL RIESGO - VALORACIÓN DE LOS CONTROLES | P7: ='Mapa de Riesgos'!Z7 -> EVALUACIÓN DEL RIESGO - NIVEL DEL RIESGO RESIDUAL | R7: PLAN DE ACCIÓN
A8: ='Mapa de Riesgos'!A8 -> No. Riesgo | B8: ='Mapa de Riesgos'!B8 -> Categoría del Riesgo | C8: ='Mapa de Riesgos'!C8 -> Clasificación del Riesgo | D8: ='Mapa de Riesgos'!D8 -> Descripción del Riesgo | E8: ='Mapa de Riesgos'!E8 -> Factores | F8: ='Mapa de Riesgos'!F8 -> Causas | G8: ='Mapa de Riesgos'!G8 -> Consecuencias | H8: ='Mapa de Riesgos'!P8 -> Zona de Riesgo Inherente | I8: ='Mapa de Riesgos'!Q8 -> No. Control | J8: ='Mapa de Riesgos'!R8 -> Descripción del Control | K8: Atributos | P8: ='Mapa de Riesgos'!AE8 -> Zona de Riesgo Final | Q8: ='Mapa de Riesgos'!AF8 -> Tratamiento | R8: Acciones | S8: Responsable | T8: Periodicidad
K9: ='Mapa de Riesgos'!T9 -> Tipo | L9: ='Mapa de Riesgos'!U9 -> Implementación | M9: ='Mapa de Riesgos'!W9 -> Documentación | N9: ='Mapa de Riesgos'!X9 -> Frecuencia | O9: ='Mapa de Riesgos'!Y9 -> Evidencia
A10: ='Mapa de Riesgos'!A10 -> 1 | B10: ='Mapa de Riesgos'!B10 -> GESTIÓN | C10: ='Mapa de Riesgos'!C10 -> Usuarios, productos y practicas , organizacionales | D10: ='Mapa de Riesgos'!D10 -> Atención no oportuna durante el proceso de inscripción. | E10: ='Mapa de Riesgos'!E10 -> Factores Internos (Debilidades) | F10: ='Mapa de Riesgos'!F10 -> 1. Insuficiencia de personal para la atención. 2. Falta de conocimiento sobre el proceso | G10: ='Mapa de Riesgos'!G10 -> 1. Pérdida de aspirantes 2. Disminución de ingresos económicos | H10: ='Mapa de Riesgos'!P10 -> Bajo | I10: ='Mapa de Riesgos'!Q10 -> 1 | J10: ='Mapa de Riesgos'!R10 -> Capacitaciones sobre atención al público y del proceso de inscripción, al personal del grupo de admisiones, registro y control académico | K10: ='Mapa de Riesgos'!T10 -> Preventivo | L10: ='Mapa de Riesgos'!U10 -> Manual | M10: ='Mapa de Riesgos'!W10 -> Documentado | N10: ='Mapa de Riesgos'!X10 -> Aleatoria | O10: ='Mapa de Riesgos'!Y10 -> Con Registro | P10: ='Mapa de Riesgos'!AE10 -> Bajo | Q10: ='Mapa de Riesgos'!AF10 -> Reducir (mitigar) | R10: Realizar las capacitaciones sobre atención al público y del proceso de inscripción, admisión y matrícula al personal del grupo de admisiones, registro y control académico, una vez aprobado el calendario académico de cada periodo | S10: Coordinador Grupo de Admisiones, Registro y Control Académico | T10: Semestral
E11: ='Mapa de Riesgos'!E11 -> 0 | F11: ='Mapa de Riesgos'!F11 -> 0 | G11: ='Mapa de Riesgos'!G11 -> 0 | I11: ='Mapa de Riesgos'!Q11 -> 2
E12: ='Mapa de Riesgos'!E12 -> 0 | F12: ='Mapa de Riesgos'!F12 -> 0 | G12: ='Mapa de Riesgos'!G12 -> 0 | I12: ='Mapa de Riesgos'!Q12 -> 3 | J12: ='Mapa de Riesgos'!R12 -> 0 | K12: ='Mapa de Riesgos'!T12 -> 0 | L12: ='Mapa de Riesgos'!U12 -> 0 | M12: ='Mapa de Riesgos'!W12 -> 0 | N12: ='Mapa de Riesgos'!X12 -> 0 | O12: ='Mapa de Riesgos'!Y12 -> 0 | P12: ='Mapa de Riesgos'!AE12 | Q12: ='Mapa de Riesgos'!AF12 -> 0
E13: ='Mapa de Riesgos'!E13 -> 0 | F13: ='Mapa de Riesgos'!F13 -> 0 | G13: ='Mapa de Riesgos'!G13 -> 0 | I13: ='Mapa de Riesgos'!Q13 -> 4 | J13: ='Mapa de Riesgos'!R13 -> 0 | K13: ='Mapa de Riesgos'!T13 -> 0 | L13: ='Mapa de Riesgos'!U13 -> 0 | M13: ='Mapa de Riesgos'!W13 -> 0 | N13: ='Mapa de Riesgos'!X13 -> 0 | O13: ='Mapa de Riesgos'!Y13 -> 0 | P13: ='Mapa de Riesgos'!AE13 | Q13: ='Mapa de Riesgos'!AF13 -> 0
E14: ='Mapa de Riesgos'!E14 -> 0 | F14: ='Mapa de Riesgos'!F14 -> 0 | G14: ='Mapa de Riesgos'!G14 -> 0 | I14: ='Mapa de Riesgos'!Q14 -> 5 | J14: ='Mapa de Riesgos'!R14 -> 0 | K14: ='Mapa de Riesgos'!T14 -> 0 | L14: ='Mapa de Riesgos'!U14 -> 0 | M14: ='Mapa de Riesgos'!W14 -> 0 | N14: ='Mapa de Riesgos'!X14 -> 0 | O14: ='Mapa de Riesgos'!Y14 -> 0 | P14: ='Mapa de Riesgos'!AE14 | Q14: ='Mapa de Riesgos'!AF14 -> 0
E15: ='Mapa de Riesgos'!E15 -> 0 | F15: ='Mapa de Riesgos'!F15 -> 0 | G15: ='Mapa de Riesgos'!G15 -> 0 | I15: ='Mapa de Riesgos'!Q15 -> 6 | J15: ='Mapa de Riesgos'!R15 -> 0 | K15: ='Mapa de Riesgos'!T15 -> 0 | L15: ='Mapa de Riesgos'!U15 -> 0 | M15: ='Mapa de Riesgos'!W15 -> 0 | N15: ='Mapa de Riesgos'!X15 -> 0 | O15: ='Mapa de Riesgos'!Y15 -> 0 | P15: ='Mapa de Riesgos'!AE15 | Q15: ='Mapa de Riesgos'!AF15 -> 0
A18: ELABORADO POR: | C18: PLANEACIÓN INSTITUCIONAL | G18: REVISADO POR: | H18: ='Mapa de Riesgos'!H18 -> SISTEMA INTEGRADO DE GESTIÓN SIG | P18: APROBADO POR: | R18: ='Mapa de Riesgos'!T18 -> LÍDER DEL SISTEMA INTEGRADO DE GESTIÓN
P19: FECHA APROBACIÓN | R19: ='Mapa de Riesgos'!T19 -> ABRIL DE 2022

Sheet Monitoreo de Riesgos
D1: ='Mapa de Riesgos'!D1 -> PLANEACIÓN INSTITUCIONAL
A2: ='Mapa de Riesgos'!A2 -> F - PL - 13 | D2: ='Mapa de Riesgos'!D2 -> MAPA DE RIESGOS INSTITUCIONAL
A4: NOMBRE DEL PROCESO | D4: ='Mapa de Riesgos'!D4 -> ADMISIONES Y MATRÍCULAS | K4: VIGENCIA | M4: 2025
A5: DEPENDENCIA/GRUPO/OFICINA | D5: ='Mapa de Riesgos'!D5 -> Grupo de Admisiones, Registro y Control Académico | K5: NOMBRE Y CARGO DEL LÍDER | M5: LUIS CARLOS JEREZ ARENAS - COORDINADOR GRUPO DE AMISIONES, REGISTRO Y CONTROL ACADÉMICO
A7: ='Mapa de Riesgos'!A7 -> IDENTIFICACIÓN DEL RIESGO | H7: ='Plan de Acción'!R7 -> PLAN DE ACCIÓN | K7: MONITOREO DE RIESGOS
A8: ='Mapa de Riesgos'!A8 -> No. Riesgo | B8: ='Mapa de Riesgos'!B8 -> Categoría del Riesgo | C8: ='Mapa de Riesgos'!C8 -> Clasificación del Riesgo | D8: ='Mapa de Riesgos'!D8 -> Descripción del Riesgo | E8: ='Mapa de Riesgos'!E8 -> Factores | F8: ='Mapa de Riesgos'!F8 -> Causas | G8: ='Mapa de Riesgos'!G8 -> Consecuencias | H8: ='Plan de Acción'!R8 -> Acciones | I8: ='Plan de Acción'!S8 -> Responsable | J8: ='Plan de Acción'!T8 -> Periodicidad | K8: 1er Monitoreo Enero-Febrero- Marzo- Abril | O8: 2do Monitoreo Mayo- Junio- Julio- Agosto | S8: 3er Monitoreo Septiembre- Octubre- Noviembre- Diciembre
K9: Materialización del Riesgo | L9: Actividades realizadas | M9: Evidencias | N9: Estado | O9: Materialización del Riesgo | P9: Actividades realizadas | Q9: Evidencias | R9: Estado | S9: Materialización del Riesgo | T9: Actividades realizadas | U9: Evidencias | V9: Estado
A10: ='Mapa de Riesgos'!A10 -> 1 | B10: ='Mapa de Riesgos'!B10 -> GESTIÓN | C10: ='Mapa de Riesgos'!C10 -> Usuarios, productos y practicas , organizacionales | D10: ='Mapa de Riesgos'!D10 -> Atención no oportuna durante el proceso de inscripción. | E10: ='Mapa de Riesgos'!E10 -> Factores Internos (Debilidades) | F10: ='Mapa de Riesgos'!F10 -> 1. Insuficiencia de personal para la atención. 2. Falta de conocimiento sobre el proceso | G10: ='Mapa de Riesgos'!G10 -> 1. Pérdida de aspirantes 2. Disminución de ingresos económicos | H10: ='Plan de Acción'!R10 -> Realizar las capacitaciones sobre atención al público y del proceso de inscripción, admisión y matrícula al personal del grupo de admisiones, registro y control académico, una vez aprobado el calendario académico de cada periodo | I10: ='Plan de Acción'!S10 -> Coordinador Grupo de Admisiones, Registro y Control Académico | J10: ='Plan de Acción'!T10 -> Semestral | K10: NO | L10: Capacitar al personal de apoyo del Grupo de Admisiones, Registro y Control Académico acerca de la atención óptima que se debe brindar a los usuarios internos y externos de la institución y el proceso de verificación de documentos de inscripción en el sistema académico Academusoft; y, socializar los calendarios académicos de las modalidades presencial y virtual del período académico 2025-2. | M10: Copia del formato F-SIG-08 (Acta de reunión) | N10: Finalizado
E11: ='Mapa de Riesgos'!E11 -> 0 | F11: ='Mapa de Riesgos'!F11 -> 0 | G11: ='Mapa de Riesgos'!G11 -> 0 | H11: ='Plan de Acción'!R11 -> 0 | I11: ='Plan de Acción'!S11 -> 0 | J11: ='Plan de Acción'!T11 -> 0
E12: ='Mapa de Riesgos'!E12 -> 0 | F12: ='Mapa de Riesgos'!F12 -> 0 | G12: ='Mapa de Riesgos'!G12 -> 0 | H12: ='Plan de Acción'!R12 -> 0 | I12: ='Plan de Acción'!S12 -> 0 | J12: ='Plan de Acción'!T12 -> 0
E13: ='Mapa de Riesgos'!E13 -> 0 | F13: ='Mapa de Riesgos'!F13 -> 0 | G13: ='Mapa de Riesgos'!G13 -> 0 | H13: ='Plan de Acción'!R13 -> 0 | I13: ='Plan de Acción'!S13 -> 0 | J13: ='Plan de Acción'!T13 -> 0
E14: ='Mapa de Riesgos'!E14 -> 0 | F14: ='Mapa de Riesgos'!F14 -> 0 | G14: ='Mapa de Riesgos'!G14 -> 0 | H14: ='Plan de Acción'!R14 -> 0 | I14: ='Plan de Acción'!S14 -> 0 | J14: ='Plan de Acción'!T14 -> 0
E15: ='Mapa de Riesgos'!E15 -> 0 | F15: ='Mapa de Riesgos'!F15 -> 0 | G15: ='Mapa de Riesgos'!G15 -> 0 | H15: ='Plan de Acción'!R15 -> 0 | I15: ='Plan de Acción'!S15 -> 0 | J15: ='Plan de Acción'!T15 -> 0
A18: ELABORADO POR: | C18: PLANEACIÓN INSTITUCIONAL | H18: REVISADO POR: | I18: ='Mapa de Riesgos'!H18 -> SISTEMA INTEGRADO DE GESTIÓN SIG | O18: APROBADO POR: | P18: ='Mapa de Riesgos'!T18 -> LÍDER DEL SISTEMA INTEGRADO DE GESTIÓN
O19: FECHA APROBACIÓN | P19: ='Mapa de Riesgos'!T19 -> ABRIL DE 2022

Sheet Historial de Cambios
B1: ='Mapa de Riesgos'!D1 -> PLANEACIÓN INSTITUCIONAL | F1: PÁGINA 5 DE 5
A2: ='Mapa de Riesgos'!A2 -> F - PL - 13 | B2: ='Mapa de Riesgos'!D2 -> MAPA DE RIESGOS INSTITUCIONAL | F2: ='Mapa de Riesgos'!AE2 -> VERSIÓN: 7.0
A4: HISTORIAL DE CAMBIOS
A5: DESCRIPCIÓN | F5: FECHA
A6: Se eliminan el riesgo 2 y 3, teniendo en cuenta que no son responsabilidad del proceso de Admisiones y Matrículas, sino del Grupo de Recursos Informáticos, los riesgos están relacionados con la configuración de sistema académico y financiero para la generación de las liquidaciones y demás de cada período académico y esta es una función de sistemas. | F6: 44566
A18: ELABORADO POR: | B18: ='Mapa de Riesgos'!C18 -> PLANEACIÓN INSTITUCIONAL | C18: REVISADO POR: | D18: ='Mapa de Riesgos'!H18 -> SISTEMA INTEGRADO DE GESTIÓN SIG | E18: APROBADO POR: | F18: ='Mapa de Riesgos'!T18 -> LÍDER DEL SISTEMA INTEGRADO DE GESTIÓN
E19: FECHA APROBACIÓN | F19: ='Mapa de Riesgos'!T19 -> ABRIL DE 2022

Sheet Matriz Calor Inherente
B2: Matriz de Calor Inherente | J2: Impacto
B6: Probabilidad | E6: Muy Alta 100% | J6: =IF(AND(#REF!="Muy Alta",#REF!="Leve"),CONCATENATE("R",#REF!),"") -> #REF! | L6: =IF(AND(#REF!="Muy Alta",#REF!="Leve"),CONCATENATE("R",#REF!),"") -> #REF! | N6: =IF(AND(#REF!="Muy Alta",#REF!="Leve"),CONCATENATE("R",#REF!),"") -> #REF! | P6: =IF(AND(#REF!="Muy Alta",#REF!="Menor"),CONCATENATE("R",#REF!),"") -> #REF! | R6: =IF(AND(#REF!="Muy Alta",#REF!="Menor"),CONCATENATE("R",#REF!),"") -> #REF! | T6: =IF(AND(#REF!="Muy Alta",#REF!="Menor"),CONCATENATE("R",#REF!),"") -> #REF! | V6: =IF(AND(#REF!="Muy Alta",#REF!="Moderado"),CONCATENATE("R",#REF!),"") -> #REF! | X6: =IF(AND(#REF!="Muy Alta",#REF!="Moderado"),CONCATENATE("R",#REF!),"") -> #REF! | Z6: =IF(AND(#REF!="Muy Alta",#REF!="Moderado"),CONCATENATE("R",#REF!),"") -> #REF! | AB6: =IF(AND(#REF!="Muy Alta",#REF!="Mayor"),CONCATENATE("R",#REF!),"") -> #REF! | AD6: =IF(AND(#REF!="Muy Alta",#REF!="Mayor"),CONCATENATE("R",#REF!),"") -> #REF! | AF6: =IF(AND(#REF!="Muy Alta",#REF!="Mayor"),CONCATENATE("R",#REF!),"") -> #REF! | AH6: =IF(AND(#REF!="Muy Alta",#REF!="Catastrófico"),CONCATENATE("R",#REF!),"") -> #REF! | AJ6: =IF(AND(#REF!="Muy Alta",#REF!="Catastrófico"),CONCATENATE("R",#REF!),"") -> #REF! | AL6: =IF(AND(#REF!="Muy Alta",#REF!="Catastrófico"),CONCATENATE("R",#REF!),"") -> #REF! | AO6: Extremo
J8: =IF(AND(#REF!="Muy Alta",#REF!="Leve"),CONCATENATE("R",#REF!),"") -> #REF! | L8: =IF(AND(#REF!="Muy Alta",#REF!="Leve"),CONCATENATE("R",#REF!),"") -> #REF! | N8: =IF(AND(#REF!="Muy Alta",#REF!="Leve"),CONCATENATE("R",#REF!),"") -> #REF! | P8: =IF(AND(#REF!="Muy Alta",#REF!="Menor"),CONCATENATE("R",#REF!),"") -> #REF! | R8: =IF(AND(#REF!="Muy Alta",#REF!="Menor"),CONCATENATE("R",#REF!),"") -> #REF! | T8: =IF(AND(#REF!="Muy Alta",#REF!="Menor"),CONCATENATE("R",#REF!),"") -> #REF! | V8: =IF(AND(#REF!="Muy Alta",#REF!="Moderado"),CONCATENATE("R",#REF!),"") -> #REF! | X8: =IF(AND(#REF!="Muy Alta",#REF!="Moderado"),CONCATENATE("R",#REF!),"") -> #REF! | Z8: =IF(AND(#REF!="Muy Alta",#REF!="Moderado"),CONCATENATE("R",#REF!),"") -> #REF! | AB8: =IF(AND(#REF!="Muy Alta",#REF!="Mayor"),CONCATENATE("R",#REF!),"") -> #REF! | AD8: =IF(AND(#REF!="Muy Alta",#REF!="Mayor"),CONCATENATE("R",#REF!),"") -> #REF! | AF8: =IF(AND(#REF!="Muy Alta",#REF!="Mayor"),CONCATENATE("R",#REF!),"") -> #REF! | AH8: =IF(AND(#REF!="Muy Alta",#REF!="Catastrófico"),CONCATENATE("R",#REF!),"") -> #REF! | AJ8: =IF(AND(#REF!="Muy Alta",#REF!="Catastrófico"),CONCATENATE("R",#REF!),"") -> #REF! | AL8: =IF(AND(#REF!="Muy Alta",#REF!="Catastrófico"),CONCATENATE("R",#REF!),"") -> #REF!
J10: =IF(AND(#REF!="Muy Alta",#REF!="Leve"),CONCATENATE("R",#REF!),"") -> #REF! | L10: =IF(AND(#REF!="Muy Alta",#REF!="Leve"),CONCATENATE("R",#REF!),"") -> #REF! | N10: =IF(AND(#REF!="Muy Alta",#REF!="Leve"),CONCATENATE("R",#REF!),"") -> #REF! | P10: =IF(AND(#REF!="Muy Alta",#REF!="Menor"),CONCATENATE("R",#REF!),"") -> #REF! | R10: =IF(AND(#REF!="Muy Alta",#REF!="Menor"),CONCATENATE("R",#REF!),"") -> #REF! | T10: =IF(AND(#REF!="Muy Alta",#REF!="Menor"),CONCATENATE("R",#REF!),"") -> #REF! | V10: =IF(AND(#REF!="Muy Alta",#REF!="Moderado"),CONCATENATE("R",#REF!),"") -> #REF! | X10: =IF(AND(#REF!="Muy Alta",#REF!="Moderado"),CONCATENATE("R",#REF!),"") -> #REF! | Z10: =IF(AND(#REF!="Muy Alta",#REF!="Moderado"),CONCATENATE("R",#REF!),"") -> #REF! | AB10: =IF(AND(#REF!="Muy Alta",#REF!="Mayor"),CONCATENATE("R",#REF!),"") -> #REF! | AD10: =IF(AND(#REF!="Muy Alta",#REF!="Mayor"),CONCATENATE("R",#REF!),"") -> #REF! | AF10: =IF(AND(#REF!="Muy Alta",#REF!="Mayor"),CONCATENATE("R",#REF!),"") -> #REF! | AH10: =IF(AND(#REF!="Muy Alta",#REF!="Catastrófico"),CONCATENATE("R",#REF!),"") -> #REF! | AJ10: =IF(AND(#REF!="Muy Alta",#REF!="Catastrófico"),CONCATENATE("R",#REF!),"") -> #REF! | AL10: =IF(AND(#REF!="Muy Alta",#REF!="Catastrófico"),CONCATENATE("R",#REF!),"") -> #REF!
J12: =IF(AND(#REF!="Muy Alta",#REF!="Leve"),CONCATENATE("R",#REF!),"") -> #REF! | L12: =IF(AND(#REF!="Muy Alta",#REF!="Leve"),CONCATENATE("R",#REF!),"") -> #REF! | N12: =IF(AND(#REF!="Muy Alta",#REF!="Leve"),CONCATENATE("R",#REF!),"") -> #REF! | P12: =IF(AND(#REF!="Muy Alta",#REF!="Menor"),CONCATENATE("R",#REF!),"") -> #REF! | R12: =IF(AND(#REF!="Muy Alta",#REF!="Menor"),CONCATENATE("R",#REF!),"") -> #REF! | T12: =IF(AND(#REF!="Muy Alta",#REF!="Menor"),CONCATENATE("R",#REF!),"") -> #REF! | V12: =IF(AND(#REF!="Muy Alta",#REF!="Moderado"),CONCATENATE("R",#REF!),"") -> #REF! | X12: =IF(AND(#REF!="Muy Alta",#REF!="Moderado"),CONCATENATE("R",#REF!),"") -> #REF! | Z12: =IF(AND(#REF!="Muy Alta",#REF!="Moderado"),CONCATENATE("R",#REF!),"") -> #REF! | AB12: =IF(AND(#REF!="Muy Alta",#REF!="Mayor"),CONCATENATE("R",#REF!),"") -> #REF! | AD12: =IF(AND(#REF!="Muy Alta",#REF!="Mayor"),CONCATENATE("R",#REF!),"") -> #REF! | AF12: =IF(AND(#REF!="Muy Alta",#REF!="Mayor"),CONCATENATE("R",#REF!),"") -> #REF! | AH12: =IF(AND(#REF!="Muy Alta",#REF!="Catastrófico"),CONCATENATE("R",#REF!),"") -> #REF! | AJ12: =IF(AND(#REF!="Muy Alta",#REF!="Catastrófico"),CONCATENATE("R",#REF!),"") -> #REF! | AL12: =IF(AND(#REF!="Muy Alta",#REF!="Catastrófico"),CONCATENATE("R",#REF!),"") -> #REF!
E14: Alta 80% | J14: =IF(AND(#REF!="Alta",#REF!="Leve"),CONCATENATE("R",#REF!),"") -> #REF! | L14: =IF(AND(#REF!="Alta",#REF!="Leve"),CONCATENATE("R",#REF!),"") -> #REF! | N14: =IF(AND(#REF!="Alta",#REF!="Leve"),CONCATENATE("R",#REF!),"") -> #REF! | P14: =IF(AND(#REF!="Alta",#REF!="Menor"),CONCATENATE("R",#REF!),"") -> #REF! | R14: =IF(AND(#REF!="Alta",#REF!="Menor"),CONCATENATE("R",#REF!),"") -> #REF! | T14: =IF(AND(#REF!="Alta",#REF!="Menor"),CONCATENATE("R",#REF!),"") -> #REF! | V14: =IF(AND(#REF!="Alta",#REF!="Moderado"),CONCATENATE("R",#REF!),"") -> #REF! | X14: =IF(AND(#REF!="Alta",#REF!="Moderado"),CONCATENATE("R",#REF!),"") -> #REF! | Z14: =IF(AND(#REF!="Alta",#REF!="Moderado"),CONCATENATE("R",#REF!),"") -> #REF! | AB14: =IF(AND(#REF!="Alta",#REF!="Mayor"),CONCATENATE("R",#REF!),"") -> #REF! | AD14: =IF(AND(#REF!="Alta",#REF!="Mayor"),CONCATENATE("R",#REF!),"") -> #REF! | AF14: =IF(AND(#REF!="Alta",#REF!="Mayor"),CONCATENATE("R",#REF!),"") -> #REF! | AH14: =IF(AND(#REF!="Alta",#REF!="Catastrófico"),CONCATENATE("R",#REF!),"") -> #REF! | AJ14: =IF(AND(#REF!="Alta",#REF!="Catastrófico"),CONCATENATE("R",#REF!),"") -> #REF! | AL14: =IF(AND(#REF!="Alta",#REF!="Catastrófico"),CONCATENATE("R",#REF!),"") -> #REF! | AO14: Alto
J16: =IF(AND(#REF!="Alta",#REF!="Leve"),CONCATENATE("R",#REF!),"") -> #REF! | L16: =IF(AND(#REF!="Alta",#REF!="Leve"),CONCATENATE("R",#REF!),"") -> #REF! | N16: =IF(AND(#REF!="Alta",#REF!="Leve"),CONCATENATE("R",#REF!),"") -> #REF! | P16: =IF(AND(#REF!="Alta",#REF!="Menor"),CONCATENATE("R",#REF!),"") -> #REF! | R16: =IF(AND(#REF!="Alta",#REF!="Menor"),CONCATENATE("R",#REF!),"") -> #REF! | T16: =IF(AND(#REF!="Alta",#REF!="Menor"),CONCATENATE("R",#REF!),"") -> #REF! | V16: =IF(AND(#REF!="Alta",#REF!="Moderado"),CONCATENATE("R",#REF!),"") -> #REF! | X16: =IF(AND(#REF!="Alta",#REF!="Moderado"),CONCATENATE("R",#REF!),"") -> #REF! | Z16: =IF(AND(#REF!="Alta",#REF!="Moderado"),CONCATENATE("R",#REF!),"") -> #REF! | AB16: =IF(AND(#REF!="Alta",#REF!="Mayor"),CONCATENATE("R",#REF!),"") -> #REF! | AD16: =IF(AND(#REF!="Alta",#REF!="Mayor"),CONCATENATE("R",#REF!),"") -> #REF! | AF16: =IF(AND(#REF!="Alta",#REF!="Mayor"),CONCATENATE("R",#REF!),"") -> #REF! | AH16: =IF(AND(#REF!="Alta",#REF!="Catastrófico"),CONCATENATE("R",#REF!),"") -> #REF! | AJ16: =IF(AND(#REF!="Alta",#REF!="Catastrófico"),CONCATENATE("R",#REF!),"") -> #REF! | AL16: =IF(AND(#REF!="Alta",#REF!="Catastrófico"),CONCATENATE("R",#REF!),"") -> #REF!
J18: =IF(AND(#REF!="Alta",#REF!="Leve"),CONCATENATE("R",#REF!),"") -> #REF! | L18: =IF(AND(#REF!="Alta",#REF!="Leve"),CONCATENATE("R",#REF!),"") -> #REF! | N18: =IF(AND(#REF!="Alta",#REF!="Leve"),CONCATENATE("R",#REF!),"") -> #REF! | P18: =IF(AND(#REF!="Alta",#REF!="Menor"),CONCATENATE("R",#REF!),"") -> #REF! | R18: =IF(AND(#REF!="Alta",#REF!="Menor"),CONCATENATE("R",#REF!),"") -> #REF! | T18: =IF(AND(#REF!="Alta",#REF!="Menor"),CONCATENATE("R",#REF!),"") -> #REF! | V18: =IF(AND(#REF!="Alta",#REF!="Moderado"),CONCATENATE("R",#REF!),"") -> #REF! | X18: =IF(AND(#REF!="Alta",#REF!="Moderado"),CONCATENATE("R",#REF!),"") -> #REF! | Z18: =IF(AND(#REF!="Alta",#REF!="Moderado"),CONCATENATE("R",#REF!),"") -> #REF! | AB18: =IF(AND(#REF!="Alta",#REF!="Mayor"),CONCATENATE("R",#REF!),"") -> #REF! | AD18: =IF(AND(#REF!="Alta",#REF!="Mayor"),CONCATENATE("R",#REF!),"") -> #REF! | AF18: =IF(AND(#REF!="Alta",#REF!="Mayor"),CONCATENATE("R",#REF!),"") -> #REF! | AH18: =IF(AND(#REF!="Alta",#REF!="Catastrófico"),CONCATENATE("R",#REF!),"") -> #REF! | AJ18: =IF(AND(#REF!="Alta",#REF!="Catastrófico"),CONCATENATE("R",#REF!),"") -> #REF! | AL18: =IF(AND(#REF!="Alta",#REF!="Catastrófico"),CONCATENATE("R",#REF!),"") -> #REF!
J20: =IF(AND(#REF!="Alta",#REF!="Leve"),CONCATENATE("R",#REF!),"") -> #REF! | L20: =IF(AND(#REF!="Alta",#REF!="Leve"),CONCATENATE("R",#REF!),"") -> #REF! | N20: =IF(AND(#REF!="Alta",#REF!="Leve"),CONCATENATE("R",#REF!),"") -> #REF! | P20: =IF(AND(#REF!="Alta",#REF!="Menor"),CONCATENATE("R",#REF!),"") -> #REF! | R20: =IF(AND(#REF!="Alta",#REF!="Menor"),CONCATENATE("R",#REF!),"") -> #REF! | T20: =IF(AND(#REF!="Alta",#REF!="Menor"),CONCATENATE("R",#REF!),"") -> #REF! | V20: =IF(AND(#REF!="Alta",#REF!="Moderado"),CONCATENATE("R",#REF!),"") -> #REF! | X20: =IF(AND(#REF!="Alta",#REF!="Moderado"),CONCATENATE("R",#REF!),"") -> #REF! | Z20: =IF(AND(#REF!="Alta",#REF!="Moderado"),CONCATENATE("R",#REF!),"") -> #REF! | AB20: =IF(AND(#REF!="Alta",#REF!="Mayor"),CONCATENATE("R",#REF!),"") -> #REF! | AD20: =IF(AND(#REF!="Alta",#REF!="Mayor"),CONCATENATE("R",#REF!),"") -> #REF! | AF20: =IF(AND(#REF!="Alta",#REF!="Mayor"),CONCATENATE("R",#REF!),"") -> #REF! | AH20: =IF(AND(#REF!="Alta",#REF!="Catastrófico"),CONCATENATE("R",#REF!),"") -> #REF! | AJ20: =IF(AND(#REF!="Alta",#REF!="Catastrófico"),CONCATENATE("R",#REF!),"") -> #REF! | AL20: =IF(AND(#REF!="Alta",#REF!="Catastrófico"),CONCATENATE("R",#REF!),"") -> #REF!
E22: Media 60% | J22: =IF(AND(#REF!="Media",#REF!="Leve"),CONCATENATE("R",#REF!),"") -> #REF! | L22: =IF(AND(#REF!="Media",#REF!="Leve"),CONCATENATE("R",#REF!),"") -> #REF! | N22: =IF(AND(#REF!="Media",#REF!="Leve"),CONCATENATE("R",#REF!),"") -> #REF! | P22: =IF(AND(#REF!="Media",#REF!="Menor"),CONCATENATE("R",#REF!),"") -> #REF! | R22: =IF(AND(#REF!="Media",#REF!="Menor"),CONCATENATE("R",#REF!),"") -> #REF! | T22: =IF(AND(#REF!="Media",#REF!="Menor"),CONCATENATE("R",#REF!),"") -> #REF! | V22: =IF(AND(#REF!="Media",#REF!="Moderado"),CONCATENATE("R",#REF!),"") -> #REF! | X22: =IF(AND(#REF!="Media",#REF!="Moderado"),CONCATENATE("R",#REF!),"") -> #REF! | Z22: =IF(AND(#REF!="Media",#REF!="Moderado"),CONCATENATE("R",#REF!),"") -> #REF! | AB22: =IF(AND(#REF!="Media",#REF!="Mayor"),CONCATENATE("R",#REF!),"") -> #REF! | AD22: =IF(AND(#REF!="Media",#REF!="Mayor"),CONCATENATE("R",#REF!),"") -> #REF! | AF22: =IF(AND(#REF!="Media",#REF!="Mayor"),CONCATENATE("R",#REF!),"") -> #REF! | AH22: =IF(AND(#REF!="Media",#REF!="Catastrófico"),CONCATENATE("R",#REF!),"") -> #REF! | AJ22: =IF(AND(#REF!="Media",#REF!="Catastrófico"),CONCATENATE("R",#REF!),"") -> #REF! | AL22: =IF(AND(#REF!="Media",#REF!="Catastrófico"),CONCATENATE("R",#REF!),"") -> #REF! | AO22: Moderado
J24: =IF(AND(#REF!="Media",#REF!="Leve"),CONCATENATE("R",#REF!),"") -> #REF! | L24: =IF(AND(#REF!="Media",#REF!="Leve"),CONCATENATE("R",#REF!),"") -> #REF! | N24: =IF(AND(#REF!="Media",#REF!="Leve"),CONCATENATE("R",#REF!),"") -> #REF! | P24: =IF(AND(#REF!="Media",#REF!="Menor"),CONCATENATE("R",#REF!),"") -> #REF! | R24: =IF(AND(#REF!="Media",#REF!="Menor"),CONCATENATE("R",#REF!),"") -> #REF! | T24: =IF(AND(#REF!="Media",#REF!="Menor"),CONCATENATE("R",#REF!),"") -> #REF! | V24: =IF(AND(#REF!="Media",#REF!="Moderado"),CONCATENATE("R",#REF!),"") -> #REF! | X24: =IF(AND(#REF!="Media",#REF!="Moderado"),CONCATENATE("R",#REF!),"") -> #REF! | Z24: =IF(AND(#REF!="Media",#REF!="Moderado"),CONCATENATE("R",#REF!),"") -> #REF! | AB24: =IF(AND(#REF!="Media",#REF!="Mayor"),CONCATENATE("R",#REF!),"") -> #REF! | AD24: =IF(AND(#REF!="Media",#REF!="Mayor"),CONCATENATE("R",#REF!),"") -> #REF! | AF24: =IF(AND(#REF!="Media",#REF!="Mayor"),CONCATENATE("R",#REF!),"") -> #REF! | AH24: =IF(AND(#REF!="Media",#REF!="Catastrófico"),CONCATENATE("R",#REF!),"") -> #REF! | AJ24: =IF(AND(#REF!="Media",#REF!="Catastrófico"),CONCATENATE("R",#REF!),"") -> #REF! | AL24: =IF(AND(#REF!="Media",#REF!="Catastrófico"),CONCATENATE("R",#REF!),"") -> #REF!
J26: =IF(AND(#REF!="Media",#REF!="Leve"),CONCATENATE("R",#REF!),"") -> #REF! | L26: =IF(AND(#REF!="Media",#REF!="Leve"),CONCATENATE("R",#REF!),"") -> #REF! | N26: =IF(AND(#REF!="Media",#REF!="Leve"),CONCATENATE("R",#REF!),"") -> #REF! | P26: =IF(AND(#REF!="Media",#REF!="Menor"),CONCATENATE("R",#REF!),"") -> #REF! | R26: =IF(AND(#REF!="Media",#REF!="Menor"),CONCATENATE("R",#REF!),"") -> #REF! | T26: =IF(AND(#REF!="Media",#REF!="Menor"),CONCATENATE("R",#REF!),"") -> #REF! | V26: =IF(AND(#REF!="Media",#REF!="Moderado"),CONCATENATE("R",#REF!),"") -> #REF! | X26: =IF(AND(#REF!="Media",#REF!="Moderado"),CONCATENATE("R",#REF!),"") -> #REF! | Z26: =IF(AND(#REF!="Media",#REF!="Moderado"),CONCATENATE("R",#REF!),"") -> #REF! | AB26: =IF(AND(#REF!="Media",#REF!="Mayor"),CONCATENATE("R",#REF!),"") -> #REF! | AD26: =IF(AND(#REF!="Media",#REF!="Mayor"),CONCATENATE("R",#REF!),"") -> #REF! | AF26: =IF(AND(#REF!="Media",#REF!="Mayor"),CONCATENATE("R",#REF!),"") -> #REF! | AH26: =IF(AND(#REF!="Media",#REF!="Catastrófico"),CONCATENATE("R",#REF!),"") -> #REF! | AJ26: =IF(AND(#REF!="Media",#REF!="Catastrófico"),CONCATENATE("R",#REF!),"") -> #REF! | AL26: =IF(AND(#REF!="Media",#REF!="Catastrófico"),CONCATENATE("R",#REF!),"") -> #REF!
J28: =IF(AND(#REF!="Media",#REF!="Leve"),CONCATENATE("R",#REF!),"") -> #REF! | L28: =IF(AND(#REF!="Media",#REF!="Leve"),CONCATENATE("R",#REF!),"") -> #REF! | N28: =IF(AND(#REF!="Media",#REF!="Leve"),CONCATENATE("R",#REF!),"") -> #REF! | P28: =IF(AND(#REF!="Media",#REF!="Menor"),CONCATENATE("R",#REF!),"") -> #REF! | R28: =IF(AND(#REF!="Media",#REF!="Menor"),CONCATENATE("R",#REF!),"") -> #REF! | T28: =IF(AND(#REF!="Media",#REF!="Menor"),CONCATENATE("R",#REF!),"") -> #REF! | V28: =IF(AND(#REF!="Media",#REF!="Moderado"),CONCATENATE("R",#REF!),"") -> #REF! | X28: =IF(AND(#REF!="Media",#REF!="Moderado"),CONCATENATE("R",#REF!),"") -> #REF! | Z28: =IF(AND(#REF!="Media",#REF!="Moderado"),CONCATENATE("R",#REF!),"") -> #REF! | AB28: =IF(AND(#REF!="Media",#REF!="Mayor"),CONCATENATE("R",#REF!),"") -> #REF! | AD28: =IF(AND(#REF!="Media",#REF!="Mayor"),CONCATENATE("R",#REF!),"") -> #REF! | AF28: =IF(AND(#REF!="Media",#REF!="Mayor"),CONCATENATE("R",#REF!),"") -> #REF! | AH28: =IF(AND(#REF!="Media",#REF!="Catastrófico"),CONCATENATE("R",#REF!),"") -> #REF! | AJ28: =IF(AND(#REF!="Media",#REF!="Catastrófico"),CONCATENATE("R",#REF!),"") -> #REF! | AL28: =IF(AND(#REF!="Media",#REF!="Catastrófico"),CONCATENATE("R",#REF!),"") -> #REF!
E30: Baja 40% | J30: =IF(AND(#REF!="Baja",#REF!="Leve"),CONCATENATE("R",#REF!),"") -> #REF! | L30: =IF(AND(#REF!="Baja",#REF!="Leve"),CONCATENATE("R",#REF!),"") -> #REF! | N30: =IF(AND(#REF!="Baja",#REF!="Leve"),CONCATENATE("R",#REF!),"") -> #REF! | P30: =IF(AND(#REF!="Baja",#REF!="Menor"),CONCATENATE("R",#REF!),"") -> #REF! | R30: =IF(AND(#REF!="Baja",#REF!="Menor"),CONCATENATE("R",#REF!),"") -> #REF! | T30: =IF(AND(#REF!="Baja",#REF!="Menor"),CONCATENATE("R",#REF!),"") -> #REF! | V30: =IF(AND(#REF!="Baja",#REF!="Moderado"),CONCATENATE("R",#REF!),"") -> #REF! | X30: =IF(AND(#REF!="Baja",#REF!="Moderado"),CONCATENATE("R",#REF!),"") -> #REF! | Z30: =IF(AND(#REF!="Baja",#REF!="Moderado"),CONCATENATE("R",#REF!),"") -> #REF! | AB30: =IF(AND(#REF!="Baja",#REF!="Mayor"),CONCATENATE("R",#REF!),"") -> #REF! | AD30: =IF(AND(#REF!="Baja",#REF!="Mayor"),CONCATENATE("R",#REF!),"") -> #REF! | AF30: =IF(AND(#REF!="Baja",#REF!="Mayor"),CONCATENATE("R",#REF!),"") -> #REF! | AH30: =IF(AND(#REF!="Baja",#REF!="Catastrófico"),CONCATENATE("R",#REF!),"") -> #REF! | AJ30: =IF(AND(#REF!="Baja",#REF!="Catastrófico"),CONCATENATE("R",#REF!),"") -> #REF! | AL30: =IF(AND(#REF!="Baja",#REF!="Catastrófico"),CONCATENATE("R",#REF!),"") -> #REF! | AO30: Bajo
